Workbook

Sheet Report Summary
B2: Data Cleaning & Reporting Automation — Run Summary
B3: Generated automatically by data_cleaning_automation.py — every number below is reproducible by rerunning the script.
B5: Metric | C5: Value
B6: Rows processed (raw) | C6: 1622
B7: Rows after cleaning | C7: 1600
B8: Duplicate rows removed | C8: 22
B9: Missing values before | C9: 253
B10: Missing values after | C10: 0
B11: Data quality score — before | C11: 98.6/100
B12: Data quality score — after | C12: 100.0/100
B13: Total revenue (cleaned) | C13: 456327.76
B14: Avg order value | C14: 285.2
B15: Return rate | C15: 0.089
B17: Column | C17: Before | D17: After
B18: Country | C18: 50 | D18: 0
B19: Discount | C19: 51 | D19: 0
B20: Email | C20: 64 | D20: 0
B21: PaymentMethod | C21: 32 | D21: 0
B22: ProductCategory | C22: 32 | D22: 0
B23: Quantity | C23: 24 | D23: 0

Sheet Cleaning Log
A1: Full audit trail of every automated cleaning action, in execution order.
A3: Time | B3: Stage | C3: Action | D3: Count
A4: 03:59:51 | B4: Ingest | C4: Loading raw file: orders_raw.csv
A5: 03:59:51 | B5: Ingest | C5: Loaded 1622 rows, 11 columns
A6: 03:59:51 | B6: Validate | C6: Missing values by column (before): Email=64, Country=50, ProductCategory=32, Quantity=24, Discount=51, PaymentMethod=32
A7: 03:59:51 | B7: Validate | C7: Exact duplicate rows found | D7: 22
A8: 03:59:51 | B8: Clean | C8: Removed exact duplicate rows | D8: 22
A9: 03:59:51 | B9: Standardize | C9: 'ProductCategory': normalized 1251 inconsistent values to canonical labels | D9: 1251
A10: 03:59:51 | B10: Standardize | C10: 'Country': normalized 1211 inconsistent values to canonical labels | D10: 1211
A11: 03:59:51 | B11: Standardize | C11: 'OrderDate': parsed 1600 mixed-format date strings into a single format
A12: 03:59:51 | B12: Standardize | C12: 'UnitPrice': converted 1600 string-formatted currency values to numeric | D12: 1600
A13: 03:59:51 | B13: Standardize | C13: 'IsReturned': collapsed 8 representations (Yes/Y/true/1, etc.) into True/False
A14: 03:59:51 | B14: Clean | C14: Flagged and nulled 11 impossible Discount value(s) (outside 0-100%) | D14: 11
A15: 03:59:51 | B15: Impute | C15: 'ProductCategory': filled 32 missing value(s) with mode ('Home & Garden') | D15: 32
A16: 03:59:51 | B16: Impute | C16: 'Country': filled 48 missing value(s) with mode ('United Kingdom') | D16: 48
A17: 03:59:51 | B17: Impute | C17: 'PaymentMethod': filled 32 missing value(s) with 'Unknown' | D17: 32
A18: 03:59:51 | B18: Impute | C18: 'Quantity': filled 24 missing value(s) with median (3.0) | D18: 24
A19: 03:59:51 | B19: Impute | C19: 'Discount': filled 59 missing value(s) (incl. flagged outliers) with median (0.15) | D19: 59
A20: 03:59:51 | B20: Impute | C20: 'Email': filled 64 missing value(s) with placeholder | D20: 64
A21: 03:59:51 | B21: Validate | C21: Missing values remaining (after) | D21: 0
A22: 03:59:51 | B22: Validate | C22: Duplicate rows remaining (after) | D22: 0
A23: 03:59:51 | B23: Report | C23: Data quality score before cleaning: 98.6/100
A24: 03:59:51 | B24: Report | C24: Data quality score after cleaning: 100.0/100

Sheet Raw Data
A1: Exactly as exported — inconsistent casing, mixed date formats, currency strings, missing values, and duplicate rows all left in place.
A3: OrderID | B3: OrderDate | C3: CustomerName | D3: Email | E3: Country | F3: ProductCategory | G3: Quantity | H3: UnitPrice | I3: Discount | J3: PaymentMethod | K3: IsReturned
A4: ORD-21390 | B4: 07-May-2026 | C4: Customer 1490 | D4: customer1490@example.com | E4: CANADA | F4: Apparel | G4: 2 | H4: 70.76 | I4: 0.08 | J4: Credit Card | K4: No
A5: ORD-20002 | B5: 26-Jun-2025 | C5: Customer 1002 | D5: customer1002@example.com | E5: DE | F5: Apparel | G5: 1 | H5: $122.24 | I5: 0.18 | J5: Credit Card | K5: false
A6: ORD-20503 | B6: April 07, 2025 | C6: Customer 1503 | D6: customer1503@example.com | E6: AUS | F6: Home & Garden | G6: 3 | H6: $197.06 | I6: 0.13 | J6: Gift Card | K6: 0
A7: ORD-21340 | B7: 2026-01-31 | C7: Customer 1440 | D7: customer1440@example.com | E7: United kingdom | F7: electronics | G7: 5 | H7: 24.27 | I7: 0.07 | K7: FALSE
A8: ORD-21025 | B8: 09/17/2025 | C8: Customer 1125 | D8: customer1125@example.com | E8: USA | F8: Sports | G8: 1 | H8: $149.32 | I8: 0.18 | J8: Credit Card | K8: No
A9: ORD-20472 | B9: 2025-12-09 | C9: Customer 1472 | D9: customer1472@example.com | E9: America | F9: Sport | G9: 1 | H9: $51.30 | J9: Credit Card | K9: FALSE
A10: ORD-20481 | B10: 07/16/2025 | C10: Customer 1481 | D10: customer1481@example.com | E10: UK | F10: Sport | G10: 2 | H10: $140.65 | I10: 0.26 | J10: PayPal | K10: no
A11: ORD-20368 | B11: 2025-09-14 | C11: Customer 1368 | D11: customer1368@example.com | E11: United States | F11: Home & Garden | G11: 4 | H11: 25.65 | I11: 0.15 | J11: PayPal | K11: No
A12: ORD-20458 | B12: 30-Jan-2026 | C12: Customer 1458 | D12: customer1458@example.com | E12: AUS | F12: apparel | G12: 4 | H12: $80.58 | I12: 0.07 | J12: PayPal | K12: No
A13: ORD-20861 | B13: 05/19/2026 | C13: Customer 1861 | D13: customer1861@example.com | E13: england | F13: Beuaty | G13: 3 | H13: $54.61 | I13: 0.02 | J13: Debit Card | K13: No
A14: ORD-20592 | B14: 2026-05-06 | C14: Customer 1592 | D14: customer1592@example.com | E14: America | F14: SPORTS | G14: 2 | H14: 23.74 | I14: 0.25 | J14: Credit Card | K14: TRUE
A15: ORD-21498 | B15: 19-Sep-2025 | C15: Customer 1598 | D15: customer1598@example.com | E15: USA | F15: Sports | G15: 3 | H15: $66.88 | I15: 0.22 | J15: PayPal | K15: FALSE
A16: ORD-21448 | B16: 2026-07-05 | C16: Customer 1548 | D16: customer1548@example.com | E16: America | F16: Sports | G16: 5 | H16: 179.61 | I16: 0.24 | J16: Credit Card | K16: No
A17: ORD-21372 | B17: 2026-07-27 | C17: Customer 1472 | D17: customer1472@example.com | E17: United states | F17: ELECTRONICS | G17: 1 | H17: 119.87 | I17: 0.05 | J17: PayPal | K17: FALSE
A18: ORD-20626 | B18: 01-Aug-2025 | C18: Customer 1626 | D18: customer1626@example.com | E18: england | F18: Electronics | G18: 5 | H18: $121.12 | I18: 0.04 | J18: Debit Card | K18: false
A19: ORD-20174 | B19: 20-Sep-2025 | C19: Customer 1174 | D19: customer1174@example.com | E19: us | F19: Apparel | G19: 3 | H19: $123.22 | I19: 0.16 | J19: Debit Card | K19: false
A20: ORD-20615 | B20: May 11, 2025 | C20: Customer 1615 | D20: customer1615@example.com | E20: CA | F20: Home & garden | G20: 1 | H20: $46.19 | I20: 0.22 | J20: Debit Card | K20: FALSE
A21: ORD-21194 | B21: 13-Dec-2025 | C21: Customer 1294 | D21: customer1294@example.com | E21: germany | F21: Beauty | G21: 1 | H21: $163.86 | I21: 0.01 | J21: Credit Card | K21: 0
A22: ORD-20570 | B22: 14-Sep-2025 | C22: Customer 1570 | D22: customer1570@example.com | E22: england | G22: 2 | H22: 110.87 | I22: 0.07 | J22: PayPal | K22: No
A23: ORD-20764 | B23: 2025-03-18 | C23: Customer 1764 | D23: customer1764@example.com | E23: canada | F23: SPORTS | G23: 5 | H23: 122.9 | I23: 0.11 | J23: Gift Card | K23: false
A24: ORD-20611 | B24: February 26, 2026 | C24: Customer 1611 | D24: customer1611@example.com | E24: CANADA | F24: Sport | G24: 4 | H24: 138.92 | I24: 0.13 | J24: Gift Card | K24: 1
A25: ORD-20795 | B25: April 01, 2026 | C25: Customer 1795 | D25: customer1795@example.com | E25: AUS | F25: HOME & GARDEN | G25: 3 | H25: 158.38 | I25: 0.23 | J25: Gift Card | K25: N
A26: ORD-20834 | B26: 26-May-2026 | C26: Customer 1834 | D26: customer1834@example.com | E26: United States | F26: Appreal | G26: 3 | H26: 22.72 | I26: 0.16 | J26: Gift Card | K26: N
A27: ORD-20272 | B27: 2026-06-07 | C27: Customer 1272 | D27: customer1272@example.com | E27: Canada | F27: apparel | G27: 4 | H27: 29.64 | I27: 0.06 | J27: Debit Card | K27: FALSE
A28: ORD-21362 | B28: 03-May-2026 | C28: Customer 1462 | D28: customer1462@example.com | E28: U.S.A. | F28: sports | G28: 3 | H28: 76.95 | I28: 0.22 | J28: Gift Card | K28: No
A29: ORD-20972 | B29: 2025-09-29 | C29: Customer 1072 | D29: customer1072@example.com | E29: AUSTRALIA | F29: Appreal | G29: 4 | H29: 106.45 | I29: 0.1 | J29: Debit Card | K29: 1
A30: ORD-20709 | B30: 08/09/2025 | C30: Customer 1709 | E30: AUS | F30: Beauty | G30: 5 | H30: $18.22 | I30: 0.24 | J30: Credit Card | K30: Yes
A31: ORD-20292 | B31: 2025-10-19 | C31: Customer 1292 | D31: customer1292@example.com | E31: DE | F31: Home & garden | G31: 4 | H31: $165.16 | I31: 0.2 | J31: Gift Card | K31: N
A32: ORD-20056 | B32: 2026-05-22 | C32: Customer 1056 | D32: customer1056@example.com | E32: USA | F32: apparel | G32: 3 | H32: 52.95 | I32: 0.21 | J32: Gift Card | K32: no
A33: ORD-21063 | B33: May 24, 2025 | C33: Customer 1163 | D33: customer1163@example.com | E33: United kingdom | F33: Apparel | G33: 4 | H33: $137.75 | I33: 0.11 | J33: Gift Card | K33: FALSE
A34: ORD-21358 | B34: 23-Mar-2026 | C34: Customer 1458 | D34: customer1458@example.com | E34: United kingdom | F34: sports | G34: 2 | H34: 194.95 | I34: 0.14 | J34: PayPal | K34: no
A35: ORD-21384 | B35: 2025-07-16 | C35: Customer 1484 | D35: customer1484@example.com | E35: United Kingdom | F35: Electronics | G35: 5 | H35: 174.78 | I35: 0.04 | J35: Debit Card | K35: TRUE
A36: ORD-20841 | B36: 09/18/2025 | C36: Customer 1841 | D36: customer1841@example.com | E36: U.K. | F36: Beuaty | G36: 2 | H36: 74.86 | I36: 0.3 | J36: PayPal | K36: false
A37: ORD-21215 | B37: June 09, 2026 | C37: Customer 1315 | D37: customer1315@example.com | E37: DE | F37: apparel | G37: 5 | H37: 106.93 | I37: 0.09 | J37: Debit Card | K37: false
A38: ORD-20974 | B38: 25-Feb-2026 | C38: Customer 1074 | D38: customer1074@example.com | E38: Germany | F38: Electronic | G38: 5 | H38: 98.87 | I38: 0.01 | J38: Gift Card | K38: N
A39: ORD-20311 | B39: September 20, 2025 | C39: Customer 1311 | D39: customer1311@example.com | E39: CANADA | F39: Home&Garden | G39: 3 | H39: $112.89 | I39: 0.15 | J39: Gift Card | K39: N
A40: ORD-20442 | B40: 01-Sep-2025 | C40: Customer 1442 | D40: customer1442@example.com | E40: germany | F40: beauty | G40: 4 | H40: 215.83 | I40: 0.26 | J40: Gift Card | K40: false
A41: ORD-21517 | B41: 01/12/2026 | C41: Customer 1617 | D41: customer1617@example.com | E41: U.S.A. | F41: Beauty | G41: 4 | H41: 76.22 | I41: 0.13 | J41: PayPal | K41: false
...

Sheet Cleaned Data
A1: Output of data_cleaning_automation.py — standardized categories, parsed dates, numeric currency, imputed nulls, LineTotal computed.
A3: OrderID | B3: OrderDate | C3: CustomerName | D3: Email | E3: Country | F3: ProductCategory | G3: Quantity | H3: UnitPrice | I3: Discount | J3: PaymentMethod | K3: IsReturned | L3: LineTotal
A4: ORD-21390 | B4: 2026-05-07 | C4: Customer 1490 | D4: customer1490@example.com | E4: Canada | F4: Apparel | G4: 2 | H4: 70.76 | I4: 0.08 | J4: Credit Card | K4: =FALSE() -> FALSE | L4: 130.2
A5: ORD-20002 | B5: 2025-06-26 | C5: Customer 1002 | D5: customer1002@example.com | E5: Germany | F5: Apparel | G5: 1 | H5: 122.24 | I5: 0.18 | J5: Credit Card | K5: =FALSE() -> FALSE | L5: 100.24
A6: ORD-20503 | B6: 2025-04-07 | C6: Customer 1503 | D6: customer1503@example.com | E6: Australia | F6: Home & Garden | G6: 3 | H6: 197.06 | I6: 0.13 | J6: Gift Card | K6: =FALSE() -> FALSE | L6: 514.33
A7: ORD-21340 | B7: 2026-01-31 | C7: Customer 1440 | D7: customer1440@example.com | E7: United Kingdom | F7: Electronics | G7: 5 | H7: 24.27 | I7: 0.07 | J7: Unknown | K7: =FALSE() -> FALSE | L7: 112.86
A8: ORD-21025 | B8: 2025-09-17 | C8: Customer 1125 | D8: customer1125@example.com | E8: United States | F8: Sports | G8: 1 | H8: 149.32 | I8: 0.18 | J8: Credit Card | K8: =FALSE() -> FALSE | L8: 122.44
A9: ORD-20472 | B9: 2025-12-09 | C9: Customer 1472 | D9: customer1472@example.com | E9: United States | F9: Sports | G9: 1 | H9: 51.3 | I9: 0.15 | J9: Credit Card | K9: =FALSE() -> FALSE | L9: 43.6
A10: ORD-20481 | B10: 2025-07-16 | C10: Customer 1481 | D10: customer1481@example.com | E10: United Kingdom | F10: Sports | G10: 2 | H10: 140.65 | I10: 0.26 | J10: PayPal | K10: =FALSE() -> FALSE | L10: 208.16
A11: ORD-20368 | B11: 2025-09-14 | C11: Customer 1368 | D11: customer1368@example.com | E11: United States | F11: Home & Garden | G11: 4 | H11: 25.65 | I11: 0.15 | J11: PayPal | K11: =FALSE() -> FALSE | L11: 87.21
A12: ORD-20458 | B12: 2026-01-30 | C12: Customer 1458 | D12: customer1458@example.com | E12: Australia | F12: Apparel | G12: 4 | H12: 80.58 | I12: 0.07 | J12: PayPal | K12: =FALSE() -> FALSE | L12: 299.76
A13: ORD-20861 | B13: 2026-05-19 | C13: Customer 1861 | D13: customer1861@example.com | E13: United Kingdom | F13: Beauty | G13: 3 | H13: 54.61 | I13: 0.02 | J13: Debit Card | K13: =FALSE() -> FALSE | L13: 160.55
A14: ORD-20592 | B14: 2026-05-06 | C14: Customer 1592 | D14: customer1592@example.com | E14: United States | F14: Sports | G14: 2 | H14: 23.74 | I14: 0.25 | J14: Credit Card | K14: =TRUE() -> TRUE | L14: 35.61
A15: ORD-21498 | B15: 2025-09-19 | C15: Customer 1598 | D15: customer1598@example.com | E15: United States | F15: Sports | G15: 3 | H15: 66.88 | I15: 0.22 | J15: PayPal | K15: =FALSE() -> FALSE | L15: 156.5
A16: ORD-21448 | B16: 2026-07-05 | C16: Customer 1548 | D16: customer1548@example.com | E16: United States | F16: Sports | G16: 5 | H16: 179.61 | I16: 0.24 | J16: Credit Card | K16: =FALSE() -> FALSE | L16: 682.52
A17: ORD-21372 | B17: 2026-07-27 | C17: Customer 1472 | D17: customer1472@example.com | E17: United States | F17: Electronics | G17: 1 | H17: 119.87 | I17: 0.05 | J17: PayPal | K17: =FALSE() -> FALSE | L17: 113.88
A18: ORD-20626 | B18: 2025-08-01 | C18: Customer 1626 | D18: customer1626@example.com | E18: United Kingdom | F18: Electronics | G18: 5 | H18: 121.12 | I18: 0.04 | J18: Debit Card | K18: =FALSE() -> FALSE | L18: 581.38
A19: ORD-20174 | B19: 2025-09-20 | C19: Customer 1174 | D19: customer1174@example.com | E19: United States | F19: Apparel | G19: 3 | H19: 123.22 | I19: 0.16 | J19: Debit Card | K19: =FALSE() -> FALSE | L19: 310.51
A20: ORD-20615 | B20: 2025-05-11 | C20: Customer 1615 | D20: customer1615@example.com | E20: Canada | F20: Home & Garden | G20: 1 | H20: 46.19 | I20: 0.22 | J20: Debit Card | K20: =FALSE() -> FALSE | L20: 36.03
A21: ORD-21194 | B21: 2025-12-13 | C21: Customer 1294 | D21: customer1294@example.com | E21: Germany | F21: Beauty | G21: 1 | H21: 163.86 | I21: 0.01 | J21: Credit Card | K21: =FALSE() -> FALSE | L21: 162.22
A22: ORD-20570 | B22: 2025-09-14 | C22: Customer 1570 | D22: customer1570@example.com | E22: United Kingdom | F22: Home & Garden | G22: 2 | H22: 110.87 | I22: 0.07 | J22: PayPal | K22: =FALSE() -> FALSE | L22: 206.22
A23: ORD-20764 | B23: 2025-03-18 | C23: Customer 1764 | D23: customer1764@example.com | E23: Canada | F23: Sports | G23: 5 | H23: 122.9 | I23: 0.11 | J23: Gift Card | K23: =FALSE() -> FALSE | L23: 546.9
A24: ORD-20611 | B24: 2026-02-26 | C24: Customer 1611 | D24: customer1611@example.com | E24: Canada | F24: Sports | G24: 4 | H24: 138.92 | I24: 0.13 | J24: Gift Card | K24: =TRUE() -> TRUE | L24: 483.44
A25: ORD-20795 | B25: 2026-04-01 | C25: Customer 1795 | D25: customer1795@example.com | E25: Australia | F25: Home & Garden | G25: 3 | H25: 158.38 | I25: 0.23 | J25: Gift Card | K25: =FALSE() -> FALSE | L25: 365.86
A26: ORD-20834 | B26: 2026-05-26 | C26: Customer 1834 | D26: customer1834@example.com | E26: United States | F26: Apparel | G26: 3 | H26: 22.72 | I26: 0.16 | J26: Gift Card | K26: =FALSE() -> FALSE | L26: 57.25
A27: ORD-20272 | B27: 2026-06-07 | C27: Customer 1272 | D27: customer1272@example.com | E27: Canada | F27: Apparel | G27: 4 | H27: 29.64 | I27: 0.06 | J27: Debit Card | K27: =FALSE() -> FALSE | L27: 111.45
A28: ORD-21362 | B28: 2026-05-03 | C28: Customer 1462 | D28: customer1462@example.com | E28: United States | F28: Sports | G28: 3 | H28: 76.95 | I28: 0.22 | J28: Gift Card | K28: =FALSE() -> FALSE | L28: 180.06
A29: ORD-20972 | B29: 2025-09-29 | C29: Customer 1072 | D29: customer1072@example.com | E29: Australia | F29: Apparel | G29: 4 | H29: 106.45 | I29: 0.1 | J29: Debit Card | K29: =TRUE() -> TRUE | L29: 383.22
A30: ORD-20709 | B30: 2025-08-09 | C30: Customer 1709 | D30: not_provided@unknown.com | E30: Australia | F30: Beauty | G30: 5 | H30: 18.22 | I30: 0.24 | J30: Credit Card | K30: =TRUE() -> TRUE | L30: 69.24
A31: ORD-20292 | B31: 2025-10-19 | C31: Customer 1292 | D31: customer1292@example.com | E31: Germany | F31: Home & Garden | G31: 4 | H31: 165.16 | I31: 0.2 | J31: Gift Card | K31: =FALSE() -> FALSE | L31: 528.51
A32: ORD-20056 | B32: 2026-05-22 | C32: Customer 1056 | D32: customer1056@example.com | E32: United States | F32: Apparel | G32: 3 | H32: 52.95 | I32: 0.21 | J32: Gift Card | K32: =FALSE() -> FALSE | L32: 125.49
A33: ORD-21063 | B33: 2025-05-24 | C33: Customer 1163 | D33: customer1163@example.com | E33: United Kingdom | F33: Apparel | G33: 4 | H33: 137.75 | I33: 0.11 | J33: Gift Card | K33: =FALSE() -> FALSE | L33: 490.39
A34: ORD-21358 | B34: 2026-03-23 | C34: Customer 1458 | D34: customer1458@example.com | E34: United Kingdom | F34: Sports | G34: 2 | H34: 194.95 | I34: 0.14 | J34: PayPal | K34: =FALSE() -> FALSE | L34: 335.31
A35: ORD-21384 | B35: 2025-07-16 | C35: Customer 1484 | D35: customer1484@example.com | E35: United Kingdom | F35: Electronics | G35: 5 | H35: 174.78 | I35: 0.04 | J35: Debit Card | K35: =TRUE() -> TRUE | L35: 838.94
A36: ORD-20841 | B36: 2025-09-18 | C36: Customer 1841 | D36: customer1841@example.com | E36: United Kingdom | F36: Beauty | G36: 2 | H36: 74.86 | I36: 0.3 | J36: PayPal | K36: =FALSE() -> FALSE | L36: 104.8
A37: ORD-21215 | B37: 2026-06-09 | C37: Customer 1315 | D37: customer1315@example.com | E37: Germany | F37: Apparel | G37: 5 | H37: 106.93 | I37: 0.09 | J37: Debit Card | K37: =FALSE() -> FALSE | L37: 486.53
A38: ORD-20974 | B38: 2026-02-25 | C38: Customer 1074 | D38: customer1074@example.com | E38: Germany | F38: Electronics | G38: 5 | H38: 98.87 | I38: 0.01 | J38: Gift Card | K38: =FALSE() -> FALSE | L38: 489.41
A39: ORD-20311 | B39: 2025-09-20 | C39: Customer 1311 | D39: customer1311@example.com | E39: Canada | F39: Home & Garden | G39: 3 | H39: 112.89 | I39: 0.15 | J39: Gift Card | K39: =FALSE() -> FALSE | L39: 287.87
A40: ORD-20442 | B40: 2025-09-01 | C40: Customer 1442 | D40: customer1442@example.com | E40: Germany | F40: Beauty | G40: 4 | H40: 215.83 | I40: 0.26 | J40: Gift Card | K40: =FALSE() -> FALSE | L40: 638.86
A41: ORD-21517 | B41: 2026-01-12 | C41: Customer 1617 | D41: customer1617@example.com | E41: United States | F41: Beauty | G41: 4 | H41: 76.22 | I41: 0.13 | J41: PayPal | K41: =FALSE() -> FALSE | L41: 265.25
...

Sheet Visual Summary
B2: Automated Visual Summary
B4: Category | C4: Revenue | D4: Orders
B5: Apparel | C5: =SUMIF('Cleaned Data'!$F$4:$F$1603,$B5,'Cleaned Data'!$L$4:$L$1603) -> 89581.46 | D5: =COUNTIF('Cleaned Data'!$F$4:$F$1603,$B5) -> 310
B6: Beauty | C6: =SUMIF('Cleaned Data'!$F$4:$F$1603,$B6,'Cleaned Data'!$L$4:$L$1603) -> 89737.49 | D6: =COUNTIF('Cleaned Data'!$F$4:$F$1603,$B6) -> 315
B7: Electronics | C7: =SUMIF('Cleaned Data'!$F$4:$F$1603,$B7,'Cleaned Data'!$L$4:$L$1603) -> 82577.49 | D7: =COUNTIF('Cleaned Data'!$F$4:$F$1603,$B7) -> 296
B8: Home & Garden | C8: =SUMIF('Cleaned Data'!$F$4:$F$1603,$B8,'Cleaned Data'!$L$4:$L$1603) -> 103390.67 | D8: =COUNTIF('Cleaned Data'!$F$4:$F$1603,$B8) -> 362
B9: Sports | C9: =SUMIF('Cleaned Data'!$F$4:$F$1603,$B9,'Cleaned Data'!$L$4:$L$1603) -> 91040.65 | D9: =COUNTIF('Cleaned Data'!$F$4:$F$1603,$B9) -> 317
B12: Country | C12: Revenue | D12: Orders
B13: Australia | C13: =SUMIF('Cleaned Data'!$E$4:$E$1603,$B13,'Cleaned Data'!$L$4:$L$1603) -> 88653.23 | D13: =COUNTIF('Cleaned Data'!$E$4:$E$1603,$B13) -> 328
B14: Canada | C14: =SUMIF('Cleaned Data'!$E$4:$E$1603,$B14,'Cleaned Data'!$L$4:$L$1603) -> 82311.79 | D14: =COUNTIF('Cleaned Data'!$E$4:$E$1603,$B14) -> 299
B15: Germany | C15: =SUMIF('Cleaned Data'!$E$4:$E$1603,$B15,'Cleaned Data'!$L$4:$L$1603) -> 92135.31 | D15: =COUNTIF('Cleaned Data'!$E$4:$E$1603,$B15) -> 314
B16: United Kingdom | C16: =SUMIF('Cleaned Data'!$E$4:$E$1603,$B16,'Cleaned Data'!$L$4:$L$1603) -> 115028.21 | D16: =COUNTIF('Cleaned Data'!$E$4:$E$1603,$B16) -> 382
B17: United States | C17: =SUMIF('Cleaned Data'!$E$4:$E$1603,$B17,'Cleaned Data'!$L$4:$L$1603) -> 78199.22 | D17: =COUNTIF('Cleaned Data'!$E$4:$E$1603,$B17) -> 277
